Workbook

Sheet Metadata
A2: Doc | B2: Num Of Reqs
A3: SDV_8217 | B3: =COUNTA(SRS_SDV_8217!A:A) -> 32
A4: SDV_2017 | B4: =COUNTA(SRS_SDV_2017!A:A) -> 5
A5: SDV_8201
A6: SDV_8002

Sheet SDV_8217
A1: SysArchReqID | B1: Milestone | C1: Description | D1: Design Notes
A2: SPM_0001 | C2: Mechatronic devices SHALL have a single software entity for both Software Manager and Power Manager. | D2: SWCD --> CDD with two periodic runnables: one for Software Manager Main fucntion the oether for Power Manager
A3: SPM_0002 | C3: SPM SHALL directly use the standard AUTOSAR BSW stack to accomplish the following standard wakeup and shutdown requests: • SDV2 Wakeup Frame (frame definition details covered in SDV-2017) • TC10 Wakeups sent directly from MCU to its Ethernet port | D3: Configuration of the RTA-CAR Project with Can and Ethernet Stack and allows the integration of the SPM in that scenario.
A4: SPM_0003 | C4: SPM SHALL utilize the DeviceCustomWakeup interface to the Hardware Power Function (“Helper App”) to accomplish the required wakeup and shutdown requests not handled through the BSW Stack. | D4: SPM is only a coordinator of wake-up frame traffic. No action about Shutdown and Wake-up prcedure are in charge to it.
A5: SPM_0004 | C5: The DeviceCustomWakeup interface SHALL consist of a bitfield 64 bits long between the Power Manager and the Wakeup Helper Function to represent requests for hardware activation | D5: Helper function is a callout from SPM perspective. Helper function is really project-specific, so that SPM can handle it allowing the confgiuration of the callout function name in SPM configuration. The callout signature shall take as input the 64 bits of the SPM generated wake-up frame according to external and internal request.
A6: SPM_0005 | C6: The bitfield SHALL follow the bit definitions specific for the Wakeup Frame in SDV-2017. | D6: Refer here
A7: SPM_0007 | C7: The Hardware Power Function SHALL deactivate its output functions if the DeviceCustomInterface interface has not been registered with ControlRequest = Hardware Activation Requested within a calibratable period of time. | D7: Need to clarification from customer. Doubt is: 1. Is in scope to SPM configuration or out-of-scope
A8: SPM_0008 | C8: Hardware Power Function code is expected to vary across the different mechatronic deployments. Each deployment SHALL specify which of the HardwareEntity enumerations it supports activating | D8: Need to clarification from customer. Doubt is: 1. Is in scope to SPM configuration or out-of-scope
A9: SPM_0009 | C9: The Hardware Power Function deployments in builds connected to the SDV2 CAN Wakeup Line SHALL support reception of the SDV2 Wakeup Frame and perform the wakeup functions corresponding to the pertinent bits as described in SDV-2017. | D9: Refere here. The desing decision is to keep the SPM has CanIf upper layer. The reference to the CanIf Pdu are configuration parameters in SPM configuration.
A10: SPM_0010 | C10: SUM SPM SHALL provide a sender receiver interface SPM_LossOfNodeIndication_Ifc as described below to provide Loss of Node Indication on-change to SUM SSFM that in turn sets/clears a Loss Of Node DTC. The on-change behavior means that the interface publishes only the node dtc/status that has changed since the last time the interface was published. dataElement associated to the SPM_LossOfNodeIndication_Ifc interface: SPM_LossOfNodeIndication_Ifc.DataElement{ uint16* nodeDtcCodeValue, // 2 bytes DTC Code Value uint8* nodeStatus, // LOST: Node is lost, RECOVERED: Node is not lost uint16 nodeListLength // Node List length } Where: enum nodeStatus { LOST = 0x00, RECOVERED = 0x01 }
A11: SPM_0011 | C11: SUM SPM SHALL provide a client server operation SPM_GetDTCIdentifier as described below to enable SUM SSFM to obtain the DTC identifier (2-bytes DTC code value) associated with an IP address in the Power Graph. This value will be used to facilitate the proper Loss Of Node, Loss of Function, and Invalid Data DTC setting. SPM_GetDTCIdentifier operation signature: -API Name: SPM_GetDTCIdentifier - Syntax Void SPM_GetDTCIdentifier ( uint32 ipAddress, uint16* dtcCodeValue )Parameters (in) ipAddress: 4 bytes IP address Parameters (inout) None Parameters (out) dtcCodeValue: 2 bytes DTC Code Value Return Value None
A12: SPM_0012 | C12: The SPM SHALL ignore any Compute Resource information conveyed in an Activation Profile request. | D12: No need to be configured.
A13: SPM_0019 | C13: SUM_SSM SHALL implement a port, PermitExecution, which can receive notification from SUM_SUSD to execute its functions or prepare for shutdown. RATIONALE: SUM_SPM should only execute when the ECU infrastructure services are ready. SUM_SUSD determines this for all applications. SUM_SPM may use the configuration SPM_PermitExection_Mask in its logic to allow configuration of which PermitExectution bits are considered to trigger a start of its functions. RATIONALE: Allow changes to the required bits in the SUSD_SPM_PermitExecution interface to be configured without requiring further SW logic changes. | D13: SUSD is providing the information about ECU HW resource status. SPM configure the information about which element in the PermitExecution bit map are necessary to be checked for being executed.
A14: SPM_0020 | C14: If SUM_SPM has no project specific dependency on HW, then SUM_SPM SHALL start execution of its functions when the Wakeup(s) Active bit in the SUSD_SPM_PermitExecution interface is TRUE | D14: Specific use case of the previous desing decision and requirements.
A15: SPM_0021 | C15: When the ECU Reset bit in the PermitExecution bit is FALSE, then SUM_SPM SHALL set its ShutdownPermission to Enable to support ECU reprogramming. | D15: Shutdown permission from SPM is a rolling counter. If counter is FULL-SCALE (0xFFu), then SPM is currently voting for going in shutdown.
A16: SPM_0022 | C16: The SPM SHALL use the PDU meta-data to store/retrieve the remote address of the PDU before the PDU transmission / after the PDU reception respectively instead of using the Set/GetRemoteAddress APIs from SoAd module. | D16: The metadata should be directly managed by S/R communication with RTE. The communication in RTE plugin has been selected for SOME-IP communication. At the moment RTE does not support the metadata handling, So that a SPM callout is implemented for each SPM configured PDU in Tx. The callout attach the metadata to the Pdus before Com forwarding them to the PduR. Tha callout needs to be configured in the COM module.
A17: SPM_0023 | C17: Heartbeat deadline monitoring Shall be managed within the SPM. RATIONALE: The heartbeat is a single PDU that is used to receive heartbeats from multiple remote nodes with different source ID. Therefore, the SPM would need to keep track of each remote node’s heartbeat se | D17: SPM acts as Master/Subordinate - As Master: start DTC Timer for target Device as soon as target wake-up frame has been sent (positive return value of function and Tx confirmation) - As Subordinate: Start the DTC Timer for waking device (configured as a Target device in Pgtt without waking path) as soon as a request comes to SPM by SM frame. If DTC timer reaches the Timeout for a target Device, the LostOfCom with Nod eis set.
A18: SPM_0024 | C18: The SPM communication through the RTE SHALL be conveyed through 4 different PDUs as described below: ❑ One Rx PDU assigned to local multicast group referred to as “SPM_HB_Rx“. ▪ Used to receive the Heartbeat ▪ Remote address is retrieved at runtime after the PDU reception ▪ Fixed Local port number for the PM traffic as defined in SDV-2017 ❑ One unicast Rx PDU assigned to local unicast address referred to as “SPM_Rx“ ▪ Used to receive the Activate/De-activate/PP_Status messages ▪ Remote address is retrieved at runtime after the PDU reception ▪ Fixed Local port number for the PM traffic as defined in SDV-2017 ❑ One Tx PDU assigned to local unicast address referred to as: “SPM_Tx” ▪ Used to transmit the Activate/De-activate/PP_Status/Req_Ack ▪ Remote address is set at runtime before the PDU transmission ▪ Fixed remote port number for the PM traffic as defined in SDV-2017 ❑ One Tx PDU assigned to local unicast address referred to as: “SPM_HB_Tx” ▪ Used to transmit the Heartbeat messages ▪ Remote address is set as the multicast address ▪ Fixed remote port number for the PM traffic as defined in SDV-2017
A19: SPM_0025 | C19: SPM SHALL transmit and receive the Wakeup Frames using the AUOTSAR stack on: 1. Ethernet. 2. CAN if the device is connected to the Wakeup CAN Network | D19: CAN --> CanIf and CanSM ETH --> EthSM, UdpNM (?), EthIf, SoAd, TcpIp
A20: SPM_0026 | C20: SPM SHALL transmit the Wakeup Frame setting the appropriate bits every 10ms | D20: Static Configuration of the SPM PM main Function periodicity
A21: SPM_0027 | C21: When transmitting the Wakeup Frame, SPM SHALL set the bits by applying “OR” logic to the following: 1. the bits required based on internal requests from the Power Graph Traversal Table. 2. the bits received from any incoming Wakeup Frame (either CAN or Ethernet) that has been received since the last time SPM transmitted the Wakeup Frame. Example if the Wakeup Frame was 4 bits in length: internal requests (0100) OR Rx Wakeup Frame 1 (0001) OR RX Wakeup Frame 2 (1000) = Tx Wakeup Frame (1101)
A22: SPM_0028 | C22: SPM SHALL send the same bitfield to the Wakeup Helper Function as sent to the Wakeup Frame (in the same software execution cycle).
A23: SPM_0031 | C23: SUM SPM SHALL do the following when attempting to activate an activation profile: 1. Find if the profile dependencies are remotely provided services by using the Sd_GetNodeAddress API defined in SDV-8201. If the IP Address is found for these dependencies, the SPM sends a remote ACTIVATE command as defined in SDV-2017. 2. For the profile dependencies that are local AND the profile dependencies that are remote with the activation status received as “ACTIVATED”, SPM uses the SUM SrvcMgr client server operation SrvcMgr_ActivateServices defined in SDV-8201 to activate the profile dependencies. 3. For every profile dependency in Step 2: a) If the return value of the service activation operation SrvcMgr_ActivateServices is E_OK_LOCAL_ENABLED or E_OK_REMOTE_ENABLED, SPM enables the corresponding PDU-Group for that service. b) If the service is unknown or calibrated off (return value is E_DISABLED or E_NOT_OK) the SPM skips activating PDUs for this dependency.
A24: SPM_0032 | C24: SUM SPM SHALL do the following when attempting to de-activate an activation profile: 1. Find if the profile dependencies are remotely provided services by using the Sd_GetNodeAddress API defined in SDV-8201. If the IP Address is found for these dependencies, the SPM sends a remote DE-ACTIVATE command as defined in SDV-2017. 2. For the profile dependencies that are local AND the profile dependencies that are remote with the de-activation status received as “DEACTIVATED”, SPM uses the SUM SrvcMgr client server operation SrvcMgr_ActivateServices defined in SDV_8201 to de-activate the profile dependencies. 3. For every profile dependency in Step 2: a) If the return value of the service de-activation operation SrvcMgr_ActivateServices is E_OK_LOCAL_ENABLED or E_OK_REMOTE_ENABLED, SPM disables the corresponding PDU-Group for that service. b) If the service is unknown or calibrated off (return value is E_DISABLED or E_NOT_OK) the SPM skips deactivating PDUs for this dependency.
A25: SPM_0033 | C25: SUM SPM SHALL provide a sender receiver interface SPM_ServiceActivationStatusNotification_Ifc as described below to provide Indication to other SUMs (SSFM, SSC ..etc.) about the activated service list and if setting a DTC is allowed based on DTC suppression Timer as defined in SDV-8002. SUM SSFM uses that to determine services to start monitoring and when to inhibit setting of DTCs (Loss of Function, invalid data…etc). SPM_ServiceActivationStatusNotification_Ifc interface dataElement definition: SPM_ServiceActivationStatusNotification_Ifc.DataElement{ Uint16* serviceIdList, // List of Services Activated bool* dtcAllowedList, // List of DTC Allowed Boolean uint16 listLength // Length of the 2 output lists } NOTE: The dtcAllowed flag will be set to true by default and will never change. There is no plan to use this flag in the initial usage of the SPM because the SPM waits for the status of the activated activation profile to be “ACTIVATED” before activating the services and the PDU groups as specified in [SPM_0031] and [SPM_0032] NOTE: The list will maintain the up to date active services list at any point in time and should not change in the case of losing the Heartbeat of a remote device with a profile that the local SPM has activated (i.e. Loss of Node DTC should not affect this interface so that the Loss of Function can occur)
A26: SPM_0034 | C26: SUM SPM SHALL interact with the Ethernet StateManager (EthSM) to trigger the transmission of a TC10 wakeup pulse. | D26: Under Discussion with the Etas Ethernet Team
A27: SPM_0035 | C27: The SPM SHALL provide an API SPM_ActivateProfile to allow local SWCs to activate profiles. The return value SHALL be E_NOT_OK if the profile is unknown for the SPM. SPM_ActivateProfile operation signature: API Name SPM_ActivateProfile Syntax Std_ReturnType SPM_ActivateProfile ( uint32 profileId ) Parameters (in) profileId: 4 bytes profile Id Parameters (inout) None Parameters (out) None Return Value Std_ReturnType (E_OK, E_NOT_OK)
A28: SPM_0036 | C28: The SPM SHALL provide an API SPM_DeactivateProfile to allow local SWCs to deactivate profiles. The return value SHALL be E_NOT_OK if the profile is unknown for the SPM. SPM_DeactivateProfile operation signature: API Name SPM_DeactivateProfile Syntax Std_ReturnType SPM_DeactivateProfile ( uint32 profileId ) Parameters (in) profileId: 4 bytes profile Id Parameters (inout) None Parameters (out) None Return Value Std_ReturnType (E_OK, E_NOT_OK)
A29: SPM_0037 | C29: The SPM module SHALL maintain for different links (physical or virtual links) a separate configuration instance within the SPM configuration. RATIONALE: To allow SPM to support ECUs that are connected to more than one ethernet link. | D29: This can be done in the configuration of the Power Graph Traversal Table in the SPM container. The mapping between Power Profile and Target Device is done at run-time: 1. evaluating the possibility to have a buffer or 2. checking each time the Sd table gm will provide an input in order to map with a multiplicity 1-to-1 a waking Device with a Target Device. So that it is not required to modify the configuration in order to map a power profile to a Waking Device Ip
A30: SPM_0038 | C30: SUM_SPM SHALL implement a port, ShutdownPermission, that publishes notification to SUM_SUSD to control the disable or enable of shutting down the ECU. | D30: As other SUMs
A31: SPM_0039 | C31: If at least one Profile in the ECU is active, then SUM_SPM SHALL set the status of ShutdownPermission to disabled. If no Profiles in the ECU are active, then SUM_SPM shall set the status of ShutdownPermisison to enabled. RATIONALE: If there is any active Profile, then the ECU should not shut down. | D31: Check in SM main function. The SM main function is implemented as a Finite State Machine. SM is in running state when SUSD requests the execution of the SPM functionalities and SPM stays in running still a local power profile has on-going activities. Activities on Power Profile for the SPM instance can be detected reading the status of the Power Profile Management Finite state Machine or using a local buffer that stores the History or the current status of activities on Power profiles.
A32: SPM_0040 | C32: SPM SHALL ensure that all received requests are handled and not overwritten or dropped RATIONALE: All SM/PM traffic will be received on the same PDU so must be retrieved/stored prior to the next one being received. | D32: The SPM port to Send/Receive SM Pdu signals are hanlded by a queued communication. The queue size depends from SPM configuration from power profiles

Sheet SRS_SDV_8217
A1: SRS | B1: Requirement Source | C1: Requirement Status | D1: Requirement Revision | E1: Requirement Tracking | F1: Validation Technique
A2: {="[$"&"SRS_SPM "&TEXT(CELL("riga",2:2)-1,"0000")&"]"} -> [$SRS_SPM 0001] | B2: Customer Spec Track | C2: Accepted | E2: {=HYPERLINK(CELL("indirizzo",SDV_8217!A2),SDV_8217!A2)} -> SPM_0001
A3: {="[$"&"SRS_SPM "&TEXT(CELL("riga",3:3)-1,"0000")&"]"} -> [$SRS_SPM 0002] | B3: Customer Spec Track | C3: Accepted | E3: {=HYPERLINK(CELL("indirizzo",SDV_8217!A3),SDV_8217!A3)} -> SPM_0002
A4: {="[$"&"SRS_SPM "&TEXT(CELL("riga",4:4)-1,"0000")&"]"} -> [$SRS_SPM 0003] | B4: Customer Spec Track | C4: Accepted | E4: {=HYPERLINK(CELL("indirizzo",SDV_8217!A4),SDV_8217!A4)} -> SPM_0003
A5: {="[$"&"SRS_SPM "&TEXT(CELL("riga",5:5)-1,"0000")&"]"} -> [$SRS_SPM 0004] | B5: Customer Spec Track | C5: Accepted | E5: {=HYPERLINK(CELL("indirizzo",SDV_8217!A5),SDV_8217!A5)} -> SPM_0004
A6: {="[$"&"SRS_SPM "&TEXT(CELL("riga",6:6)-1,"0000")&"]"} -> [$SRS_SPM 0005] | B6: Customer Spec Track | C6: Accepted | E6: {=HYPERLINK(CELL("indirizzo",SDV_8217!A6),SDV_8217!A6)} -> SPM_0005
A7: {="[$"&"SRS_SPM "&TEXT(CELL("riga",7:7)-1,"0000")&"]"} -> [$SRS_SPM 0006] | B7: Customer Spec Track | C7: Accepted | E7: {=HYPERLINK(CELL("indirizzo",SDV_8217!A7),SDV_8217!A7)} -> SPM_0007
A8: {="[$"&"SRS_SPM "&TEXT(CELL("riga",8:8)-1,"0000")&"]"} -> [$SRS_SPM 0007] | B8: Customer Spec Track | C8: Accepted | E8: {=HYPERLINK(CELL("indirizzo",SDV_8217!A8),SDV_8217!A8)} -> SPM_0008
A9: {="[$"&"SRS_SPM "&TEXT(CELL("riga",9:9)-1,"0000")&"]"} -> [$SRS_SPM 0008] | B9: Customer Spec Track | C9: Accepted | E9: {=HYPERLINK(CELL("indirizzo",SDV_8217!A9),SDV_8217!A9)} -> SPM_0009
A10: {="[$"&"SRS_SPM "&TEXT(CELL("riga",10:10)-1,"0000")&"]"} -> [$SRS_SPM 0009] | B10: Customer Spec Track | C10: Accepted | E10: {=HYPERLINK(CELL("indirizzo",SDV_8217!A10),SDV_8217!A10)} -> SPM_0010
A11: {="[$"&"SRS_SPM "&TEXT(CELL("riga",11:11)-1,"0000")&"]"} -> [$SRS_SPM 0010] | B11: Customer Spec Track | C11: Accepted | E11: {=HYPERLINK(CELL("indirizzo",SDV_8217!A11),SDV_8217!A11)} -> SPM_0011
A12: {="[$"&"SRS_SPM "&TEXT(CELL("riga",12:12)-1,"0000")&"]"} -> [$SRS_SPM 0011] | B12: Customer Spec Track | C12: Accepted | E12: {=HYPERLINK(CELL("indirizzo",SDV_8217!A12),SDV_8217!A12)} -> SPM_0012
A13: {="[$"&"SRS_SPM "&TEXT(CELL("riga",13:13)-1,"0000")&"]"} -> [$SRS_SPM 0012] | B13: Customer Spec Track | C13: Accepted | E13: {=HYPERLINK(CELL("indirizzo",SDV_8217!A13),SDV_8217!A13)} -> SPM_0019
A14: {="[$"&"SRS_SPM "&TEXT(CELL("riga",14:14)-1,"0000")&"]"} -> [$SRS_SPM 0013] | B14: Customer Spec Track | C14: Accepted | E14: {=HYPERLINK(CELL("indirizzo",SDV_8217!A14),SDV_8217!A14)} -> SPM_0020
A15: {="[$"&"SRS_SPM "&TEXT(CELL("riga",15:15)-1,"0000")&"]"} -> [$SRS_SPM 0014] | B15: Customer Spec Track | C15: Accepted | E15: {=HYPERLINK(CELL("indirizzo",SDV_8217!A15),SDV_8217!A15)} -> SPM_0021
A16: {="[$"&"SRS_SPM "&TEXT(CELL("riga",16:16)-1,"0000")&"]"} -> [$SRS_SPM 0015] | B16: Customer Spec Track | C16: Accepted | E16: {=HYPERLINK(CELL("indirizzo",SDV_8217!A16),SDV_8217!A16)} -> SPM_0022
A17: {="[$"&"SRS_SPM "&TEXT(CELL("riga",17:17)-1,"0000")&"]"} -> [$SRS_SPM 0016] | B17: Customer Spec Track | C17: Accepted | E17: {=HYPERLINK(CELL("indirizzo",SDV_8217!A17),SDV_8217!A17)} -> SPM_0023
A18: {="[$"&"SRS_SPM "&TEXT(CELL("riga",18:18)-1,"0000")&"]"} -> [$SRS_SPM 0017] | B18: Customer Spec Track | C18: Accepted | E18: {=HYPERLINK(CELL("indirizzo",SDV_8217!A18),SDV_8217!A18)} -> SPM_0024
A19: {="[$"&"SRS_SPM "&TEXT(CELL("riga",19:19)-1,"0000")&"]"} -> [$SRS_SPM 0018] | B19: Customer Spec Track | C19: Accepted | E19: {=HYPERLINK(CELL("indirizzo",SDV_8217!A19),SDV_8217!A19)} -> SPM_0025
A20: {="[$"&"SRS_SPM "&TEXT(CELL("riga",20:20)-1,"0000")&"]"} -> [$SRS_SPM 0019] | B20: Customer Spec Track | C20: Accepted | E20: {=HYPERLINK(CELL("indirizzo",SDV_8217!A20),SDV_8217!A20)} -> SPM_0026
A21: {="[$"&"SRS_SPM "&TEXT(CELL("riga",21:21)-1,"0000")&"]"} -> [$SRS_SPM 0020] | B21: Customer Spec Track | C21: Accepted | E21: {=HYPERLINK(CELL("indirizzo",SDV_8217!A21),SDV_8217!A21)} -> SPM_0027
A22: {="[$"&"SRS_SPM "&TEXT(CELL("riga",22:22)-1,"0000")&"]"} -> [$SRS_SPM 0021] | B22: Customer Spec Track | C22: Accepted | E22: {=HYPERLINK(CELL("indirizzo",SDV_8217!A22),SDV_8217!A22)} -> SPM_0028
A23: {="[$"&"SRS_SPM "&TEXT(CELL("riga",23:23)-1,"0000")&"]"} -> [$SRS_SPM 0022] | B23: Customer Spec Track | C23: Accepted | E23: {=HYPERLINK(CELL("indirizzo",SDV_8217!A23),SDV_8217!A23)} -> SPM_0031
A24: {="[$"&"SRS_SPM "&TEXT(CELL("riga",24:24)-1,"0000")&"]"} -> [$SRS_SPM 0023] | B24: Customer Spec Track | C24: Accepted | E24: {=HYPERLINK(CELL("indirizzo",SDV_8217!A24),SDV_8217!A24)} -> SPM_0032
A25: {="[$"&"SRS_SPM "&TEXT(CELL("riga",25:25)-1,"0000")&"]"} -> [$SRS_SPM 0024] | B25: Customer Spec Track | C25: Accepted | E25: {=HYPERLINK(CELL("indirizzo",SDV_8217!A25),SDV_8217!A25)} -> SPM_0033
A26: {="[$"&"SRS_SPM "&TEXT(CELL("riga",26:26)-1,"0000")&"]"} -> [$SRS_SPM 0025] | B26: Customer Spec Track | C26: Accepted | E26: {=HYPERLINK(CELL("indirizzo",SDV_8217!A26),SDV_8217!A26)} -> SPM_0034
A27: {="[$"&"SRS_SPM "&TEXT(CELL("riga",27:27)-1,"0000")&"]"} -> [$SRS_SPM 0026] | B27: Customer Spec Track | C27: Accepted | E27: {=HYPERLINK(CELL("indirizzo",SDV_8217!A27),SDV_8217!A27)} -> SPM_0035
A28: {="[$"&"SRS_SPM "&TEXT(CELL("riga",28:28)-1,"0000")&"]"} -> [$SRS_SPM 0027] | B28: Customer Spec Track | C28: Accepted | E28: {=HYPERLINK(CELL("indirizzo",SDV_8217!A28),SDV_8217!A28)} -> SPM_0036
A29: {="[$"&"SRS_SPM "&TEXT(CELL("riga",29:29)-1,"0000")&"]"} -> [$SRS_SPM 0028] | B29: Customer Spec Track | C29: Accepted | E29: {=HYPERLINK(CELL("indirizzo",SDV_8217!A29),SDV_8217!A29)} -> SPM_0037
A30: {="[$"&"SRS_SPM "&TEXT(CELL("riga",30:30)-1,"0000")&"]"} -> [$SRS_SPM 0029] | B30: Customer Spec Track | C30: Accepted | E30: {=HYPERLINK(CELL("indirizzo",SDV_8217!A30),SDV_8217!A30)} -> SPM_0038
A31: {="[$"&"SRS_SPM "&TEXT(CELL("riga",31:31)-1,"0000")&"]"} -> [$SRS_SPM 0030] | B31: Customer Spec Track | C31: Accepted | E31: {=HYPERLINK(CELL("indirizzo",SDV_8217!A31),SDV_8217!A31)} -> SPM_0039
A32: {="[$"&"SRS_SPM "&TEXT(CELL("riga",32:32)-1,"0000")&"]"} -> [$SRS_SPM 0031] | B32: Customer Spec Track | C32: Accepted | E32: {=HYPERLINK(CELL("indirizzo",SDV_8217!A32),SDV_8217!A32)} -> SPM_0040

Sheet SDV_2017
A1: SysArchReqID | B1: Milestone | C1: Description | D1: Design Notes | E1: Marginal notes
A2: SDVA-4873 | B2: Software Manager | C2: Each swEntity MUST have one and only one SM that is responsible for the final determination of whether that swEntity is to be started or stopped. | D2: OUT_OF_SCOPE | E2: Is job of the integrator take this into account
A3: SDVA-4874 | B3: Activation Profile Management | C3: SM's activating a software entity hosted on a remote host SHALL identify the location of the responsible remote SM as the IP address of the swEntity itself. | D3: DONE
A4: SDVA-4875 | B4: Software Manager | C4: Each host MUST have only one SM that is responsible for all of the swEntities on that host. | D4: DONE
A5: SDVA-5379 | B5: Activation Profile Management | C5: The SM of each host SHALL inform its local PM that it has the need for the localhost by sending the PowerOnDevice request specifying the IP address of the localhost. | D5: DONE
A6: SDVA-4876 | B6: Activation Profile Management | C6: The SM of each host SHALL inform its local PM that its need for the localhost has ended by sending the PowerOffDevice request specifying the IP address of the localhost. | D6: DONE
A7: SDVA-4877 | B7: Activation Profile Management | C7: SM SHALL activate a swEntity it manages based on the following information: -internal state of the SM (e.g. the default state may require a set of default swEntities) -requests (local or remote) made to the SM for that swEntity | D7: DONE
A8: SDVA-4878 | B8: Activation Profile Management | C8: SM SHALL deactivate a swEntity it manages when there are no active requests for profiles of this swEntity. | D8: DONE
A9: SDVA-4879 | B9: Activation Profile Management | C9: The request for activation of a swEntity to the SM SHALL be made in the form of an activation request of an activation profile of that swEntity. | D9: DONE
A10: SDVA-5416 | B10: Activation Profile Management | C10: SPM maintains a list of Requester Nodes for each managed Profile | D10: DONE
A11: SDVA-5417 | B11: Activation Profile Management | C11: WHEN SPM receives an Activation Request for Profile <X> and Profile <X> is in Inactive State, the SPM: • Add the Requester ID to the List of Requester for Profile <X> • Set the Profile <X> State to Activating. | D11: DONE
A12: SDVA-5418 | B12: Activation Profile Management | C12: WHEN SPM receives a Deactivation Request for Profile <X> and Profile <X> is in Inactive State, the SPM takes no action on Profile <X> state value. | D12: DONE
A13: SDVA-5419 | B13: Activation Profile Management | C13: WHEN SPM receives a Deactivation Request for Profile <X> and Profile <X> is in Activating State, the SPM: • Remove the Requetser ID from Requester List for Profile <X> AND check the actual size of the Requester List • IF Requester List Size is 0, THEN SPM sets the Profile <X> State to Deactivating • ELSE SPM does not change the Profile <X> state WHILE Profile <X> is in Activating state, SPM: 1. Activating profile dependencies (local and remote) 2. Performing activating step retry policy WHEN dependencies did not activate. | D13: DONE
A14: SDVA-5420 | B14: Activation Profile Management | C14: WHEN SPM receives an Activation Request for Profile <X> and Profile <X> is in Activating State, the SPM: • Add the Requester ID to Requester List for Profile <X> WHILE Profile <X> is in Activating state, SPM: 1. Activating profile dependencies (local and remote) 2. Performing activating step retry policy WHEN dependencies did not activate. | D14: DONE
A15: SDVA-5421 | B15: Activation Profile Management | C15: WHEN Profile <X> is in Activating State AND the profile-owning software entity itself is activated, the SPM set the Profile <X> state to Activated | D15: DONE
A16: SDVA-5422 | B16: Activation Profile Management | C16: WHEN SPM receives an Activation Request for Profile <X> AND Profile <X> is in Activated State, the SPM: • Add the Requester ID to Requester List for Profile <X> WHEN SPM receives an Activation Request for Profile <X> AND Profile <X> is in Activated State, the SPM: • Remove the Requetser ID from Requester List for Profile <X> AND check the actual size of the Requester List • IF Requester List Size is 0, THEN SPM sets the Profile <X> State to Deactivating • ELSE SPM does not change the Profile <X> state WHILE Profile <X> is in Activated state, SPM: 1. Monitor the Status of the remote node that hosts the SM that activated any Profile <X> remote dependency 2. Monitor the remote Profile <X> activated dependencies status 3. Apply retry policy for activating the not-yet activated dependency as per SDV-5431 | D16: DONE | E16: Miss the 'Monitor Activate profile status for any activated remote dependencies': The SM frame is received, saved inside Spm_ReqStatusPayload_Rx but no action is taken if we receive an unexpected 'INACTIVE' state of a PowProf that was previouslt ACTIVE and no deactivation request are performed
A17: SDVA-5423 | B17: Activation Profile Management | C17: WHILE Profile <X> is in Deactivating state, SPM: 1. Deactivating the profile owning software entity AND Requesting deactivation for all profile dependencies, including to apply the retries until the request has been confirmed. WHEN Profile <X> is Deactivating AND SPM detects all dependencies (local and remote) and the owning software entity Deactivated, SPM: • Sets the Profile <X> state value to Inactive IF Profile <X> Requester List is empty | D17: DONE
A18: SDVA-5424 | B18: Activation Profile Management | C18: WHEN SPM receives an Activation Request for Profile <X> AND Profile <X> is in Deactivating State, the SPM: • Add the Requester ID to Requester List for Profile <X> • Sets the Profile <X> state value to Activating IF Profile <X> Requester List is not empty | D18: DONE | E18: Take into account consideration regarding the PowerOnDevice and PowerOffDevice
A19: SDVA-5425 | B19: Activation Profile Management | C19: WHEN the state of a profile changes, the SM SHALL notify all the activation requesters of the updated profile state via the REQ_STATUS_PROF_STATE message of the SM communication frame | D19: DONE
A20: SDVA-5426 | D20: OUT_OF_SCOPE | E20: Is job of the integrator take this into account
A21: SDVA-5427 | D21: OUT_OF_SCOPE | E21: Is job of the integrator take this into account
A22: SDVA-5428 | B22: Profile Activation Request Interaction | C22: Profile activation request to a SM SHALL be made using the ActivateProfile method by passing the IDs of the requested profiles. Multiple profiles MAY be requested in one request. | D22: DONE | E22: takes just only one request in input as per SDV-8217 API specification
A23: SDVA-5429 | B23: Profile Activation Request Interaction | C23: Each SM SHALL also provide a RequestStatusProfileState interface to allow the SM to communicate the request status as well as the updated profile state to local and remote activation requesters | D23: TO_BE_DEFINED | E23: For the remote is already done with the SM frame, while for the local one is to be defined
A24: SDVA-5430 | B24: Profile Activation Request Interaction | C24: Upon receiving an activation request, the SM SHALL first determine if the request is valid and permitted. This determination SHALL be performed separately for each profile requested. • IF the request is determined to be valid and permitted, then the SM SHALL add the requester to the list of requesters for the requested profiles. • IF the requester was already on the requester list for that profile, then it does not need to be added again. ◘The SM SHALL also use MonitorDevice method to its local PM to request monitoring of a remote requester. ◘The profile state SHALL be updated appropriately based on the request. ◘The SM SHALL provide feedback to the requester using the RequestStatusProfileState interface. • If the request is determined to be invalid or not permitted, then the SM SHALL provide feedback to the requester using the RequestStatusProfileState interface, specifying the appropriate reject reason in the Request Status field and the appropriate profile state in the Profile State field. ◘ If the reject reason is REJECTED_PROFILE_UNKNOWN or REJECTED_LACK_OF_PERMISSION, then the Profile State provided SHALL be UNKNOWN. ◘If the reject reason is otherwise, then the Profile State provided SHALL be the actual state of the profile. | D24: ONGOING | E24: Miss the part about the 'provide feedback if the request is determined to be invalid or not permitted'
A25: SDVA-5431 | B25: Profile Activation Request Interaction | C25: The requesting SM SHALL retry sending the same ActivationProfile requests at a calibratable interval when no response is received, or the request is rejected. The calibration value MAY be dependent on the reject reason. But this is to be determined by the domain specific requirements. When retry is permitted, the SM can continue retry for as long as the activation criterion for the profile is still met | D25: DONE
A26: SDVA-5432 | B26: Profile Activation | C26: SM SHALL activate a profile by • activating the swEntity associated with the profile • activating the network communication for the swEntity associated with the profile • activating local swEntities specified as dependencies in the profile • activating hardware specified as dependencies in the profile • requesting activation of any remote swEntities specified as dependencies in the profile to the remote SM responsible for these remote swEntities | D26: DONE | E26: Not tracked in the code since is too general
A27: SDVA-5433 | B27: Profile Activation | C27: A profile SHALL transition into the Activated state as soon as the swEntity associated with the profile and its network communication are both activated. The activation of dependencies can continue in this activated state. Note that it is possible that a dependency cannot be activated for some reason. The SM is not responsible for setting any error codes related to this condition | D27: Which means network communication? Data-Path (data in PDU enabled by BswM mode siwtch), Control-Path (Sm nd PM frames plus wake-up frames) Or Both? (done)
A28: SDVA-5434 | B28: Profile Activation | C28: To activate HW dependencies, the SM SHALL make PowerOnDevice requests to its local PM, specifying the IDs of the hardware devices in the request. The PM would then activate the device and provide updated device state via the DevicePowerState message to the SM. | D28: DONE
A29: SDVA-4254 | B29: Profile Activation | C29: To activate a remote software dependency, the SM SHALL make ActivateProfile request to the remote SM that's responsible for that remote swEntity. However, it will only do so after first waking up the remote host that hosts this remote SM. The process follows the following steps: 1. SM determines the IP address of the remote SM based on the ID of the software dependency. 2. SM requests wakeup of this IP address through its local PM using the PowerOnDevice request, specifying the IP address in the request. It also subscribes to the state of the remote host through the DevicePowerState topic published by the PM 3. PM conducts the wake up and provides the updated status of this remote host to the SM. This status is derived based on the heartbeat of the remote host 4. When the remote host is awake, SM sends the ActivateProfile request to the remote SM. Note here that if the remote host is already awake, then the SM would be able to send the request immediately in parallel while the PM is performing the wakeup assertion. • The wakeup assertion is always perform required to ensure that the remote host stays awake 5. SM will continue to retry any activation that does not succeed | D29: DONE
A30: SDVA-4385 | B30: Profile Activation | C30: SM SHALL make the PowerOnDevice request to the PM even if the requested host is already awake. | D30: DONE
A31: SDVA-5435 | B31: Profile Deactivation | C31: Profile deactivation requests to a SM SHALL be made using the DeactivateProfile method. | D31: DONE
A32: SDVA-5436 | B32: Profile Deactivation | C32: The network communication implementation for RequestStatusProfileState is implemented using the REQ_STATUS_PROFILE_STATE message where the request status is captured by the Request Status field and the profile state is capture by the Profile State field. | D32: TO_BE_DEFINED | E32: For the remote is already done with the SM frame, while for the local one is to be defined
A33: SDVA-5437 | B33: Profile Deactivation | C33: The DeactivateProfile method SHALL only be used by an ActivateProfile requester to remove its previous activation request. In other words, one requester cannot deactivate an active profile that was made active by another requester. A request to deactivate profile from a requester that is not an activation requester SHALL result in no action performed by the SM on the profile state. If the request is received from an existing activation requester, then SM SHALL then remove the requester from the list of activation requesters for the profile requested. The SM SHALL further make a MonitorDevice request to its local PM to stop monitoring the requesting host. In both of these cases, the requester SHALL receive a REQ_STATUS_PROFILE_STATE message with the Request Status indicating OK. | D33: DONE
A34: SDVA-5438 | B34: Profile Deactivation | C34: Describe how the SM SHALL deactivate a profile. | D34: OUT_OF_SCOPE | E34: General purpose
A35: SDVA-5385 | B35: PGTT | C35: The Waking Device field is used to identify rows of the table that are pertinent to a specific PM. It is required to be supported by devices that take advantage of a common, vehicle-wide PGTT calibration. The PM SHALL: 1. treat the Waking Device field as a 4 byte value representing the PM IP Address. 2. only execute wakeup commands from PGTT entries that have its own IP Address represented in the Waking Device field. | D35: DONE
A36: SDVA-5387 | B36: PGTT | C36: The PM SHALL treat the Target Device Field as a 4 byte value representing either: 1. the IP address of the device to be woken up when that device has a PM OR 2. as a value defined elsewhere in this specification that is distinguishable from IP addresses and represents the device to be woken up when that device does not have a PM. 3. send the activation/deactivation command(s) from the PGTT row(s) where the Target Device field matches the device communicated in the PowerOnDevice and PowerOff Device requests. | D36: DONE
A37: SDVA-5388 | B37: HW (De)Activation | C37: There are cases where the device to be woken up is more than one PM away from the waking device in the Power Graph. In these cases, the Waking PM will need to (de)activate multiple PMs in sequence. The necessary commands will be identified sequentially using the Wakeup Sequence field. The PM SHALL treat the Wakeup Sequence field as a 1 byte value representing the order of wakeup command execution. Each Sequence entry will have a corresponding Wakeup Command Field. | D37: DONE | E37: Tag in the code is not located. Probably can be set in the SWCD.
A38: SDVA-5389 | B38: HW (De)Activation | C38: The PM SHALL: 1. treat the Wakeup Command as a 1 byte value representing an enumeration of wakeup commands described below. 2. send/stop sending the command corresponding to the enumerated value found in the Wakeup Command field. | D38: DONE
A39: SDVA-5390 | B39: HW (De)Activation | C39: Each Sequence entry MAY have a corresponding Wakeup Step Delay Field if intermediate nodes need time before processing further commands. The PM SHALL treat the Wakeup Step Delay Field as a 2 byte value representing a time delay in milliseconds before proceeding to the next step in the PowerOnDevice Sequence. | D39: DONE | E39: Tag in the code is not located. Probably can be set in the SWCD.
A40: SDVA-5391 | B40: HW (De)Activation | C40: The enumerations of the Wakeup Command Field SHALL be defined as follows: OPEN | D40: OUT_OF_SCOPE
...

Sheet SRS_SDV_2017
A1: SRS | B1: Requirement Source | C1: Requirement Status | D1: Requirement Revision | E1: Requirement Tracking | F1: Validation Technique
A2: {="[$"&"SRS_SPM "&TEXT(SUM(CELL("riga",2:2),Metadata!$B$3-2,),"0000")&"]"} -> [$SRS_SPM 0032] | B2: Customer Spec Track | C2: Accepted | E2: {=HYPERLINK(CELL("indirizzo",Tabella5[[#This Row],[SysArchReqID]]),Tabella5[[#This Row],[SysArchReqID]])} -> SDVA-4873
A3: {="[$"&"SRS_SPM "&TEXT(SUM(CELL("riga",3:3),Metadata!$B$3-2,),"0000")&"]"} -> [$SRS_SPM 0033] | B3: Customer Spec Track | C3: Accepted | E3: {=HYPERLINK(CELL("indirizzo",Tabella5[[#This Row],[SysArchReqID]]),Tabella5[[#This Row],[SysArchReqID]])} -> SDVA-4874
A4: {="[$"&"SRS_SPM "&TEXT(SUM(CELL("riga",4:4),Metadata!$B$3-2,),"0000")&"]"} -> [$SRS_SPM 0034] | B4: Customer Spec Track | C4: Accepted | E4: {=HYPERLINK(CELL("indirizzo",Tabella5[[#This Row],[SysArchReqID]]),Tabella5[[#This Row],[SysArchReqID]])} -> SDVA-4875
A5: {="[$"&"SRS_SPM "&TEXT(SUM(CELL("riga",5:5),Metadata!$B$3-2,),"0000")&"]"} -> [$SRS_SPM 0035] | B5: Customer Spec Track | C5: Accepted | E5: {=HYPERLINK(CELL("indirizzo",Tabella5[[#This Row],[SysArchReqID]]),Tabella5[[#This Row],[SysArchReqID]])} -> SDVA-5379
